<?xml version="1.0" encoding="utf-8"?>
<!-- This URDF was automatically created by SolidWorks to URDF Exporter! Originally created by Stephen Brawner (brawner@gmail.com) 
     Commit Version: 1.6.0-4-g7f85cfe  Build Version: 1.6.7995.38578
     For more information, please see http://wiki.ros.org/sw_urdf_exporter -->
<robot
  name="Car assembly">
  <link
    name="base_link">
    <inertial>
      <origin
        xyz="0.00062631 0.31309 -0.25258"
        rpy="0 0 0" />
      <mass
        value="33.846" />
      <inertia
        ixx="0.27315"
        ixy="-0.0016883"
        ixz="-2.0306E-05"
        iyy="0.28226"
        iyz="-0.0046629"
        izz="0.41234" />
    </inertial>
    <visual>
      <origin
        xyz="0 0 0"
        rpy="0 0 0" />
      <geometry>
        <mesh
          filename="meshes/base_link.STL" />
      </geometry>
      <material
        name="">
        <color
          rgba="0 0 0 1" />
      </material>
    </visual>
    <collision>
      <origin
        xyz="0 0 0"
        rpy="0 0 0" />
      <geometry>
        <mesh
          filename="meshes/base_link.STL" />
      </geometry>
    </collision>
  </link>
  <link
    name="right_Knuckle">
    <inertial>
      <origin
        xyz="-0.11963 -6.1676E-05 0.14233"
        rpy="0 0 0" />
      <mass
        value="3.805" />
      <inertia
        ixx="0.038868"
        ixy="3.9127E-06"
        ixz="0.021219"
        iyy="0.04605"
        iyz="-5.3928E-06"
        izz="0.026557" />
    </inertial>
    <visual>
      <origin
        xyz="0 0 0"
        rpy="0 0 0" />
      <geometry>
        <mesh
          filename="meshes/right_Knuckle.STL" />
      </geometry>
      <material
        name="">
        <color
          rgba="0.36 0.18 0.05 1" />
      </material>
    </visual>
    <collision>
      <origin
        xyz="0 0 0"
        rpy="0 0 0" />
      <geometry>
        <mesh
          filename="meshes/right_Knuckle.STL" />
      </geometry>
    </collision>
  </link>
  <joint
    name="right_Knuckle_joint"
    type="continuous">
    <origin
      xyz="-0.199999999999968 0.471319481101379 -0.372577159553223"
      rpy="3.14159265358979 0 -1.5707963267949" />
    <parent
      link="base_link" />
    <child
      link="right_Knuckle" />
    <axis
      xyz="0 -1 0" />
  </joint>
  <link
    name="right_wheel">
    <inertial>
      <origin
        xyz="-2.9254E-08 -0.00065273 2.1302E-07"
        rpy="0 0 0" />
      <mass
        value="16.633" />
      <inertia
        ixx="0.082756"
        ixy="-1.7814E-08"
        ixz="8.7481E-09"
        iyy="0.148"
        iyz="1.7679E-07"
        izz="0.082756" />
    </inertial>
    <visual>
      <origin
        xyz="0 0 0"
        rpy="0 0 0" />
      <geometry>
        <mesh
          filename="meshes/right_wheel.STL" />
      </geometry>
      <material
        name="">
        <color
          rgba="0 0 0 1" />
      </material>
    </visual>
    <collision>
      <origin
        xyz="0 0 0"
        rpy="0 0 0" />
      <geometry>
        <mesh
          filename="meshes/right_wheel.STL" />
      </geometry>
    </collision>
  </link>
  <joint
    name="right_wheel_joint"
    type="continuous">
    <origin
      xyz="-0.234395683941828 0.00250018385050004 0.29337333442125"
      rpy="0 0 0" />
    <parent
      link="right_Knuckle" />
    <child
      link="right_wheel" />
    <axis
      xyz="0 1 0" />
  </joint>
  <link
    name="right_disk">
    <inertial>
      <origin
        xyz="4.4409E-16 3.7317E-14 -1.9984E-15"
        rpy="0 0 0" />
      <mass
        value="0.072665" />
      <inertia
        ixx="6.5244E-05"
        ixy="-5.1038E-21"
        ixz="-8.5943E-21"
        iyy="0.00013048"
        iyz="-3.0297E-20"
        izz="6.5244E-05" />
    </inertial>
    <visual>
      <origin
        xyz="0 0 0"
        rpy="0 0 0" />
      <geometry>
        <mesh
          filename="meshes/right_disk.STL" />
      </geometry>
      <material
        name="">
        <color
          rgba="0.52941 0.54902 0.54902 1" />
      </material>
    </visual>
    <collision>
      <origin
        xyz="0 0 0"
        rpy="0 0 0" />
      <geometry>
        <mesh
          filename="meshes/right_disk.STL" />
      </geometry>
    </collision>
  </link>
  <joint
    name="right_disk_joint"
    type="fixed">
    <origin
      xyz="0 -0.0581328274135423 0"
      rpy="0 0 0" />
    <parent
      link="right_wheel" />
    <child
      link="right_disk" />
    <axis
      xyz="0 0 0" />
  </joint>
  <link
    name="right_encoder">
    <inertial>
      <origin
        xyz="0.0033456 -0.007696 0.00505"
        rpy="0 0 0" />
      <mass
        value="0.0018182" />
      <inertia
        ixx="1.6328E-07"
        ixy="-1.3711E-08"
        ixz="1.5168E-15"
        iyy="1.0427E-07"
        iyz="2.0502E-15"
        izz="1.2878E-07" />
    </inertial>
    <visual>
      <origin
        xyz="0 0 0"
        rpy="0 0 0" />
      <geometry>
        <mesh
          filename="meshes/right_encoder.STL" />
      </geometry>
      <material
        name="">
        <color
          rgba="1 0 0 1" />
      </material>
    </visual>
    <collision>
      <origin
        xyz="0 0 0"
        rpy="0 0 0" />
      <geometry>
        <mesh
          filename="meshes/right_encoder.STL" />
      </geometry>
    </collision>
  </link>
  <joint
    name="right_encoder"
    type="fixed">
    <origin
      xyz="-0.207097260733896 -0.0607650000000001 0.243793104335452"
      rpy="1.5707963267949 1.5707963267949 0" />
    <parent
      link="right_Knuckle" />
    <child
      link="right_encoder" />
    <axis
      xyz="0 0 0" />
  </joint>
  <link
    name="right_low_suspension">
    <inertial>
      <origin
        xyz="0.00033582 9.4025E-08 -0.021194"
        rpy="0 0 0" />
      <mass
        value="0.16486" />
      <inertia
        ixx="0.00010548"
        ixy="3.5543E-12"
        ixz="1.4135E-06"
        iyy="0.00010569"
        iyz="-2.6801E-10"
        izz="1.6291E-05" />
    </inertial>
    <visual>
      <origin
        xyz="0 0 0"
        rpy="0 0 0" />
      <geometry>
        <mesh
          filename="meshes/right_low_suspension.STL" />
      </geometry>
      <material
        name="">
        <color
          rgba="0.77647 0.75686 0.73725 1" />
      </material>
    </visual>
    <collision>
      <origin
        xyz="0 0 0"
        rpy="0 0 0" />
      <geometry>
        <mesh
          filename="meshes/right_low_suspension.STL" />
      </geometry>
    </collision>
  </link>
  <joint
    name="right_low_suspension_joint"
    type="continuous">
    <origin
      xyz="-0.128131802251497 0 0.0805394382397928"
      rpy="0 0 0" />
    <parent
      link="right_Knuckle" />
    <child
      link="right_low_suspension" />
    <axis
      xyz="0 -1 0" />
  </joint>
  <link
    name="left_knuckle">
    <inertial>
      <origin
        xyz="-0.11963 6.1684E-05 0.14233"
        rpy="0 0 0" />
      <mass
        value="3.805" />
      <inertia
        ixx="0.038868"
        ixy="-4.0185E-06"
        ixz="0.021219"
        iyy="0.04605"
        iyz="5.3105E-06"
        izz="0.026557" />
    </inertial>
    <visual>
      <origin
        xyz="0 0 0"
        rpy="0 0 0" />
      <geometry>
        <mesh
          filename="meshes/left_knuckle.STL" />
      </geometry>
      <material
        name="">
        <color
          rgba="0.36 0.18 0.05 1" />
      </material>
    </visual>
    <collision>
      <origin
        xyz="0 0 0"
        rpy="0 0 0" />
      <geometry>
        <mesh
          filename="meshes/left_knuckle.STL" />
      </geometry>
    </collision>
  </link>
  <joint
    name="left_knuckle_joint"
    type="continuous">
    <origin
      xyz="0.200000000000031 0.471319481101379 -0.372577159553224"
      rpy="3.14159265358979 0 -1.5707963267949" />
    <parent
      link="base_link" />
    <child
      link="left_knuckle" />
    <axis
      xyz="0 -1 0" />
  </joint>
  <link
    name="left_wheel">
    <inertial>
      <origin
        xyz="-4.015E-08 0.00065274 2.4461E-07"
        rpy="0 0 0" />
      <mass
        value="16.633" />
      <inertia
        ixx="0.082756"
        ixy="3.5814E-08"
        ixz="1.719E-08"
        iyy="0.148"
        iyz="-2.0763E-07"
        izz="0.082756" />
    </inertial>
    <visual>
      <origin
        xyz="0 0 0"
        rpy="0 0 0" />
      <geometry>
        <mesh
          filename="meshes/left_wheel.STL" />
      </geometry>
      <material
        name="">
        <color
          rgba="0 0 0 1" />
      </material>
    </visual>
    <collision>
      <origin
        xyz="0 0 0"
        rpy="0 0 0" />
      <geometry>
        <mesh
          filename="meshes/left_wheel.STL" />
      </geometry>
    </collision>
  </link>
  <joint
    name="left_wheel_joint"
    type="continuous">
    <origin
      xyz="-0.234395683930872 -0.00250018383990397 0.293373334432206"
      rpy="0 0 0" />
    <parent
      link="left_knuckle" />
    <child
      link="left_wheel" />
    <axis
      xyz="0 1 0" />
  </joint>
  <link
    name="left_disk">
    <inertial>
      <origin
        xyz="-6.2172E-15 4.1855E-14 -3.5527E-15"
        rpy="0 0 0" />
      <mass
        value="0.072665" />
      <inertia
        ixx="6.5244E-05"
        ixy="-5.2904E-21"
        ixz="-3.5574E-20"
        iyy="0.00013048"
        iyz="1.9946E-19"
        izz="6.5244E-05" />
    </inertial>
    <visual>
      <origin
        xyz="0 0 0"
        rpy="0 0 0" />
      <geometry>
        <mesh
          filename="meshes/left_disk.STL" />
      </geometry>
      <material
        name="">
        <color
          rgba="0.52941 0.54902 0.54902 1" />
      </material>
    </visual>
    <collision>
      <origin
        xyz="0 0 0"
        rpy="0 0 0" />
      <geometry>
        <mesh
          filename="meshes/left_disk.STL" />
      </geometry>
    </collision>
  </link>
  <joint
    name="left_disk_joint"
    type="fixed">
    <origin
      xyz="0 0.0581328274029457 0"
      rpy="0 0 0" />
    <parent
      link="left_wheel" />
    <child
      link="left_disk" />
    <axis
      xyz="0 0 0" />
  </joint>
  <link
    name="left_encoder">
    <inertial>
      <origin
        xyz="0.0082686 0.0014323 0.00505"
        rpy="0 0 0" />
      <mass
        value="0.0018182" />
      <inertia
        ixx="1.1386E-07"
        ixy="2.5729E-08"
        ixz="-1.8683E-15"
        iyy="1.5369E-07"
        iyz="1.9843E-15"
        izz="1.2878E-07" />
    </inertial>
    <visual>
      <origin
        xyz="0 0 0"
        rpy="0 0 0" />
      <geometry>
        <mesh
          filename="meshes/left_encoder.STL" />
      </geometry>
      <material
        name="">
        <color
          rgba="1 0 0 1" />
      </material>
    </visual>
    <collision>
      <origin
        xyz="0 0 0"
        rpy="0 0 0" />
      <geometry>
        <mesh
          filename="meshes/left_encoder.STL" />
      </geometry>
    </collision>
  </link>
  <joint
    name="left_encoder_joint"
    type="fixed">
    <origin
      xyz="-0.192670048049405 0.0607649999999989 0.255132329800909"
      rpy="1.5707963267949 1.5707963267949 0" />
    <parent
      link="left_knuckle" />
    <child
      link="left_encoder" />
    <axis
      xyz="0 0 0" />
  </joint>
  <link
    name="left_low_suspension">
    <inertial>
      <origin
        xyz="0.00033582 9.4025E-08 -0.021194"
        rpy="0 0 0" />
      <mass
        value="0.16486" />
      <inertia
        ixx="0.00010548"
        ixy="3.5543E-12"
        ixz="1.4135E-06"
        iyy="0.00010569"
        iyz="-2.6801E-10"
        izz="1.6291E-05" />
    </inertial>
    <visual>
      <origin
        xyz="0 0 0"
        rpy="0 0 0" />
      <geometry>
        <mesh
          filename="meshes/left_low_suspension.STL" />
      </geometry>
      <material
        name="">
        <color
          rgba="0.77647 0.75686 0.73725 1" />
      </material>
    </visual>
    <collision>
      <origin
        xyz="0 0 0"
        rpy="0 0 0" />
      <geometry>
        <mesh
          filename="meshes/left_low_suspension.STL" />
      </geometry>
    </collision>
  </link>
  <joint
    name="left_low_suspension_joint"
    type="continuous">
    <origin
      xyz="-0.128131802251497 0 0.0805394382397931"
      rpy="0 0 0" />
    <parent
      link="left_knuckle" />
    <child
      link="left_low_suspension" />
    <axis
      xyz="0 -1 0" />
  </joint>
  <link
    name="right_high_suspension">
    <inertial>
      <origin
        xyz="-0.00067655 7.1805E-05 0.046412"
        rpy="0 0 0" />
      <mass
        value="0.5159" />
      <inertia
        ixx="0.00030587"
        ixy="1.8263E-07"
        ixz="-1.1466E-07"
        iyy="0.00030586"
        iyz="2.9465E-06"
        izz="9.6782E-05" />
    </inertial>
    <visual>
      <origin
        xyz="0 0 0"
        rpy="0 0 0" />
      <geometry>
        <mesh
          filename="meshes/right_high_suspension.STL" />
      </geometry>
      <material
        name="">
        <color
          rgba="0.77647 0.75686 0.73725 1" />
      </material>
    </visual>
    <collision>
      <origin
        xyz="0 0 0"
        rpy="0 0 0" />
      <geometry>
        <mesh
          filename="meshes/right_high_suspension.STL" />
      </geometry>
    </collision>
  </link>
  <joint
    name="right_high_suspension_joint"
    type="continuous">
    <origin
      xyz="-0.199999999999969 0.597470947158883 -0.328132285703223"
      rpy="3.14159265358979 0 -1.5707963267949" />
    <parent
      link="base_link" />
    <child
      link="right_high_suspension" />
    <axis
      xyz="0 -1 0" />
  </joint>
  <link
    name="left_high_suspension">
    <inertial>
      <origin
        xyz="-0.00067655 7.1805E-05 0.046412"
        rpy="0 0 0" />
      <mass
        value="0.5159" />
      <inertia
        ixx="0.00030587"
        ixy="1.8263E-07"
        ixz="-1.1466E-07"
        iyy="0.00030586"
        iyz="2.9465E-06"
        izz="9.6782E-05" />
    </inertial>
    <visual>
      <origin
        xyz="0 0 0"
        rpy="0 0 0" />
      <geometry>
        <mesh
          filename="meshes/left_high_suspension.STL" />
      </geometry>
      <material
        name="">
        <color
          rgba="0.77647 0.75686 0.73725 1" />
      </material>
    </visual>
    <collision>
      <origin
        xyz="0 0 0"
        rpy="0 0 0" />
      <geometry>
        <mesh
          filename="meshes/left_high_suspension.STL" />
      </geometry>
    </collision>
  </link>
  <joint
    name="left_high_suspension_joint"
    type="continuous">
    <origin
      xyz="0.20000000000003 0.597470947158883 -0.328132285703224"
      rpy="3.14159265358979 0 -1.5707963267949" />
    <parent
      link="base_link" />
    <child
      link="left_high_suspension" />
    <axis
      xyz="0 -1 0" />
  </joint>
  <link
    name="right_caster">
    <inertial>
      <origin
        xyz="4.5439E-07 -0.062682 -0.030057"
        rpy="0 0 0" />
      <mass
        value="6.0737" />
      <inertia
        ixx="0.050416"
        ixy="-4.132E-08"
        ixz="-2.9361E-08"
        iyy="0.028183"
        iyz="-0.018711"
        izz="0.050879" />
    </inertial>
    <visual>
      <origin
        xyz="0 0 0"
        rpy="0 0 0" />
      <geometry>
        <mesh
          filename="meshes/right_caster.STL" />
      </geometry>
      <material
        name="">
        <color
          rgba="0.5 0.5 0.5 1" />
      </material>
    </visual>
    <collision>
      <origin
        xyz="0 0 0"
        rpy="0 0 0" />
      <geometry>
        <mesh
          filename="meshes/right_caster.STL" />
      </geometry>
    </collision>
  </link>
  <joint
    name="right_caster_joint"
    type="continuous">
    <origin
      xyz="-0.193999999999983 0.0787262973425801 -0.432906688526437"
      rpy="1.5866453347782 0 0" />
    <parent
      link="base_link" />
    <child
      link="right_caster" />
    <axis
      xyz="0 1 0" />
  </joint>
  <link
    name="right_caster_wheel">
    <inertial>
      <origin
        xyz="-1.9429E-15 1.0922E-05 -9.1593E-16"
        rpy="0 0 0" />
      <mass
        value="17.571" />
      <inertia
        ixx="0.11153"
        ixy="6.7233E-17"
        ixz="1.1926E-17"
        iyy="0.21554"
        iyz="3.2052E-16"
        izz="0.11153" />
    </inertial>
    <visual>
      <origin
        xyz="0 0 0"
        rpy="0 0 0" />
      <geometry>
        <mesh
          filename="meshes/right_caster_wheel.STL" />
      </geometry>
      <material
        name="">
        <color
          rgba="0 0 0 1" />
      </material>
    </visual>
    <collision>
      <origin
        xyz="0 0 0"
        rpy="0 0 0" />
      <geometry>
        <mesh
          filename="meshes/right_caster_wheel.STL" />
      </geometry>
    </collision>
  </link>
  <joint
    name="right_caster_wheel_joint"
    type="continuous">
    <origin
      xyz="0 -0.224100000000001 -0.118501282216464"
      rpy="0 -1.55494731881158 1.57079632679494" />
    <parent
      link="right_caster" />
    <child
      link="right_caster_wheel" />
    <axis
      xyz="0 -1 0" />
  </joint>
  <link
    name="left_caster">
    <inertial>
      <origin
        xyz="4.7087E-07 -0.062683 -0.030057"
        rpy="0 0 0" />
      <mass
        value="6.0737" />
      <inertia
        ixx="0.050416"
        ixy="-4.1304E-08"
        ixz="-2.9361E-08"
        iyy="0.028183"
        iyz="-0.018711"
        izz="0.050879" />
    </inertial>
    <visual>
      <origin
        xyz="0 0 0"
        rpy="0 0 0" />
      <geometry>
        <mesh
          filename="meshes/left_caster.STL" />
      </geometry>
      <material
        name="">
        <color
          rgba="0.5 0.5 0.5 1" />
      </material>
    </visual>
    <collision>
      <origin
        xyz="0 0 0"
        rpy="0 0 0" />
      <geometry>
        <mesh
          filename="meshes/left_caster.STL" />
      </geometry>
    </collision>
  </link>
  <joint
    name="left_caster_joint"
    type="continuous">
    <origin
      xyz="0.194000000000024 0.0787262973425764 -0.432906688526438"
      rpy="1.5866453347782 0 0" />
    <parent
      link="base_link" />
    <child
      link="left_caster" />
    <axis
      xyz="0 1 0" />
  </joint>
  <link
    name="left_caster_wheel">
    <inertial>
      <origin
        xyz="-6.5503E-15 1.0922E-05 3.6082E-15"
        rpy="0 0 0" />
      <mass
        value="17.571" />
      <inertia
        ixx="0.11153"
        ixy="9.8903E-17"
        ixz="-5.3819E-18"
        iyy="0.21554"
        iyz="3.5392E-17"
        izz="0.11153" />
    </inertial>
    <visual>
      <origin
        xyz="0 0 0"
        rpy="0 0 0" />
      <geometry>
        <mesh
          filename="meshes/left_caster_wheel.STL" />
      </geometry>
      <material
        name="">
        <color
          rgba="0 0 0 1" />
      </material>
    </visual>
    <collision>
      <origin
        xyz="0 0 0"
        rpy="0 0 0" />
      <geometry>
        <mesh
          filename="meshes/left_caster_wheel.STL" />
      </geometry>
    </collision>
  </link>
  <joint
    name="left_caster_wheel_joint"
    type="continuous">
    <origin
      xyz="0 -0.224099999999996 -0.118501282216458"
      rpy="0 -1.55494731881158 1.57079632679494" />
    <parent
      link="left_caster" />
    <child
      link="left_caster_wheel" />
    <axis
      xyz="0 -1 0" />
  </joint>
  <link
    name="bag">
    <inertial>
      <origin
        xyz="-0.15515 -0.12633 -0.0015414"
        rpy="0 0 0" />
      <mass
        value="0.32197" />
      <inertia
        ixx="0.0029346"
        ixy="-9.6493E-07"
        ixz="-1.2181E-05"
        iyy="0.0027009"
        iyz="9.899E-08"
        izz="0.0056301" />
    </inertial>
    <visual>
      <origin
        xyz="0 0 0"
        rpy="0 0 0" />
      <geometry>
        <mesh
          filename="meshes/bag.STL" />
      </geometry>
      <material
        name="">
        <color
          rgba="1 0.61961 0 1" />
      </material>
    </visual>
    <collision>
      <origin
        xyz="0 0 0"
        rpy="0 0 0" />
      <geometry>
        <mesh
          filename="meshes/bag.STL" />
      </geometry>
    </collision>
  </link>
  <joint
    name="bag_joint"
    type="continuous">
    <origin
      xyz="-0.12675 0.41098 0.010715"
      rpy="3.1416 0 -1.5708" />
    <parent
      link="base_link" />
    <child
      link="bag" />
    <axis
      xyz="0 -1 0" />
  </joint>
</robot>